Workbook
Name その他経費: '[1]直近データ (損益)'!$H$57:$H$60
Name その他経費2: '[1]直近データ (製造原価)'!$H$69:$H$70
Name 単位: [1]直近データ!$J$8:$J$12
Name 福利厚生: '[1]直近データ (損益)'!$I$57:$I$58

Sheet スタート
A1: 会社名 | C1: ひながた | F1: 第 | G1: 4 | H1: 期 | I1: 製作：結城伸太郎
A2: 自 | B2: 45170 | C2: 例：2024/11/1
A3: 至 | B3: 45505 | C3: 現状 | D3: （百万円） | E3: 例：122 → 1億2200万円
D4: 1
A5: コードNo | B5: 勘定科目 | C5: 損益計算書 | D5: 製造原価報告書
A6: 売上 | B6: 直近売上 | C6: 355 | E6: 直近売上(現状)
A7: 総益 | B7: 売上総利益 | C7: 130.1 | E7: 売上総利益
A8: 益率 | B8: 利益率(%) | C8: =IFERROR(C7/C6,"") -> 0.36647887 | E8: 利益率(0.**)
E9: 変動費
E10: 粗利益率(0.**)
E11: 粗利益額
A12: 人件1 | B12: 社員給料 | C12: 22 | E12: 社員給料
A13: 人件2 | B13: 通勤手当 | E13: 通勤手当
A14: 人件3 | B14: 賞与 | C14: 4 | D14: 3 | E14: 賞与
A15: 人件4 | B15: 退職金 | E15: 退職金
A16: 人件5 | B16: 雑給料 | C16: 0.5 | E16: 雑給料
A17: 人件6 | B17: 派遣社員費 | E17: 派遣社員費
A18: 人件7 | B18: 契約社員費 | E18: 契約社員費
A19: 人件8 | B19: 諸費用 | E19: 諸費用
A20: 人件9 | B20: 役員報酬 | C20: 15 | E20: 役員報酬
A21: 人件10 | B21: 募集費 | E21: 募集費
A22: 人件11 | B22: 教育研修 | E22: 教育研修
A23: 人件12 | B23: 研修費 | E23: 研修費
A24: 人件13 | B24: 会議費 | E24: 会議費
A25: 人件14 | B25: 予備 | E25: 図書教育費
A26: 人件15 | B26: 予備 | E26: 新聞図書費
A27: 人件16 | B27: 福利厚生費 | C27: 5 | D27: 5 | E27: 福利厚生費
A28: 人件17 | B28: 法定福利費 | C28: 9 | D28: 12 | E28: 法定福利費
A29: 事業費1 | B29: 事業戦略費 | E29: 開拓手数料 | F29: 事業戦略費
A30: 事業費2 | B30: 社長戦略費Ａ | E30: 役員報酬 | F30: 社長戦略費Ａ
A31: 事業費3 | B31: 社長戦略費Ｂ | E31: 販売促進費 | F31: 社長戦略費Ｂ
A32: 事業費4 | B32: 開拓手数料(外交員) | E32: 企画料 | F32: 開拓手数料(外交員)
A33: 事業費5 | B33: 消耗資材費 | E33: 消耗資材費 | F33: テナント料
A34: 事業費6 | B34: ロイヤリティー | E34: 運賃 | F34: ロイヤリティー
A35: 事業費7 | B35: 外注加工費 | E35: 外注加工費 | F35: 販売促進費
A36: 事業費8 | B36: 運賃荷造費 | E36: 運賃荷造費 | F36: 企画料
A37: 販促費1 | B37: テナント料 | E37: 包装費 | F37: 消耗資材費
A38: 販促費2 | B38: 包装費 | F38: 試供品ＤＭ費
A39: 販促費3 | B39: 販売企画費 | F39: 外注加工費
A40: 販促費4 | B40: 試供品ＤＭ費 | F40: 運賃荷造費
...

Sheet MQ（現状）
B1: =スタート!C1 -> ひながた
B2: MQ会計(現状） （百万円） | U2: 製作：結城伸太郎
B3: =スタート!C6 -> 355 | F3: =スタート!G102 -> 224.9 | L3: 1.1 | P3: × | Q3: 320
B13: =L3*Q3 -> 352 | F13: =スタート!C7 -> 130.1 | H13: =スタート!G103 -> 103.8 | L13: 11 | P13: × | Q13: 11
H18: =スタート!G105+スタート!C102-スタート!C103+スタート!C105-スタート!C106 -> 46.3
B24: メモ：

Sheet ①利益
A1: =スタート!C1 -> ひながた
A2: ①利益を決めよう （百万円）例：2000万円→20 | P2: 製作：結城伸太郎
A3: 営業利益 | B3: 25 | F3: 百万円 | H3: 特別利益 | I3: 10 | M3: 百万円
A4: 営業外収益 | B4: 10 | F4: 百万円 | H4: 特別損失 | I4: 0 | M4: 百万円
A5: 営業外費用 | B5: 0 | F5: 百万円 | H5: 税引前利益 | I5: =B6+I3-I4 -> 45 | M5: 百万円
A6: 経常利益 | B6: =B3+B4-B5 -> 35 | F6: 百万円
H7: 前年対比 | I7: =I5/スタート!G106 -> 0.97192225

Sheet ②⑧MQ（未来）
B1: =スタート!C1 -> ひながた
B2: ②MQ会計(未来） （百万円） | L2: １件当たりの客単価 | Q2: 数 | V2: 製作：結城伸太郎
B3: =⑦原価詳細!F31/1000000 -> 450 | F3: ='⑥製造（経費)'!I2 -> 273.6 | L3: =⑦原価詳細!E31 -> 588235.29 | P3: × | Q3: =⑦原価詳細!D31 -> 765
I10: =F3/B3 -> 0.608
F13: =B3-F3 -> 176.4 | H13: =④経費!I2*1000000/1000000 -> 130.4 | L13: 0 | P13: × | Q13: 0
G16: =F13/B3 -> 0.392 | I16: =H13/B3 -> 0.28977778
F17: =⑦原価詳細!B36/1000000-F13 -> -0.00451
H18: =F13-H13 -> 46
I21: =H18/B3 -> 0.10222222
H22: 目標値 | I22: =①利益!I5 -> 45
B24: ①まず初めにGの目標値を決めましょう。これは社長自身がいくらの利益を残したいのかを決定させる重要な課題です。 すべての決断は社長自身にあります。思い切った利益を追求しましょう！ ②～⑤まで順番に現状から推移して115％～200％UPまで好きな数字を目標値に入れてください。 数字が合うように計算しましょう。 １，GはM-Fです。 ２，FはM-Gです。 ３．MはP-Vです。 ４．VはP-Mです。 ５．PはM＋Vです。 | L24: メモ：

Sheet ③給料
A1: =スタート!C1 -> ひながた
A2: ③（Ｆ）人件費を入力する（内勤・営業） | Q2: 製作：結城伸太郎
E3: （百万円） | J3: （百万円） | O3: （百万円）
B4: 人件費明細 | D4: 年収を記入 | G4: 雑給料 | I4: 年収を記入 | L4: 派遣社員 | N4: 年収を記入
B5: 区分・テーブル | C5: 単価 | D5: 人数 | E5: 合計 | G5: 区分・テーブル | H5: 単価 | I5: 人数 | J5: 合計 | L5: 区分・テーブル | M5: 単価 | N5: 人数 | O5: 合計
B6: 社員１ | C6: 3.5 | D6: 3 | E6: =C6*D6 -> 10.5 | G6: パート１ | H6: 0.5 | I6: 2 | J6: =H6*I6 -> 1 | L6: 派遣社員1 | M6: 0 | N6: 0 | O6: =M6*N6 -> 0
B7: 社員２ | C7: 3.3 | D7: 4 | E7: =C7*D7 -> 13.2 | G7: パート２ | H7: 0 | I7: 0 | J7: =H7*I7 -> 0 | L7: 派遣社員2 | M7: 0 | N7: 0 | O7: =M7*N7 -> 0
B8: 社員３ | C8: 3 | D8: 3 | E8: =C8*D8 -> 9 | G8: パート３ | H8: 0 | I8: 0 | J8: =H8*I8 -> 0 | L8: 派遣社員3 | M8: 0 | N8: 0 | O8: =M8*N8 -> 0
B9: 社員４ | C9: 0 | D9: 0 | E9: =C9*D9 -> 0 | G9: パート４ | H9: 0 | I9: 0 | J9: =H9*I9 -> 0 | L9: 派遣社員4 | M9: 0 | N9: 0 | O9: =M9*N9 -> 0
B10: 社員５ | C10: 0 | D10: 0 | E10: =C10*D10 -> 0 | G10: パート５ | H10: 0 | I10: 0 | J10: =H10*I10 -> 0 | L10: 派遣社員5 | M10: 0 | N10: 0 | O10: =M10*N10 -> 0
B11: 社員６ | C11: 0 | D11: 0 | E11: =C11*D11 -> 0 | G11: アルバイト１ | H11: 0 | I11: 0 | J11: =H11*I11 -> 0 | L11: 派遣社員6 | M11: 0 | N11: 0 | O11: =M11*N11 -> 0
B12: 社員７ | C12: 0 | D12: 0 | E12: =C12*D12 -> 0 | G12: アルバイト２ | H12: 0 | I12: 0 | J12: =H12*I12 -> 0 | L12: 契約社員１ | M12: 0 | N12: 0 | O12: =M12*N12 -> 0
B13: 社員８ | C13: 0 | D13: 0 | E13: =C13*D13 -> 0 | G13: アルバイト３ | H13: 0 | I13: 0 | J13: =H13*I13 -> 0 | L13: 契約社員２ | M13: 0 | N13: 0 | O13: =M13*N13 -> 0
B14: 社員給料 | C14: 計 | D14: =SUM(D6:D13) -> 10 | E14: =SUM(E6:E13) -> 32.7 | G14: 雑給料 | H14: 計 | I14: =SUM(I6:I13) -> 2 | J14: =SUM(J6:J13) -> 1 | L14: 派遣社員費 | M14: 計 | N14: =SUM(N6:N13) -> 0 | O14: =SUM(O6:O13) -> 0
B15: 給料（現状） | C15: 計 | D15: 8 | E15: =スタート!C12 -> 22 | G15: 雑給料（現状） | H15: 計 | I15: 1 | J15: =スタート!C16 -> 0.5 | L15: 派遣社員費 （現状） | M15: 計 | O15: =スタート!C17+スタート!C18 -> 0
B17: 平均年収 | E17: 上昇率
B18: 未来 | C18: =(E14+J14+O14)/(D14+I14+N14) -> 2.8083333 | D18: 百万円 | E18: =C18/C19 -> 1.1233333
B19: 現状 | C19: =IFERROR((E15+J15+O15)/(N15+I15+D15),"0") -> 2.5 | D19: 百万円

Sheet ④経費
A1: =スタート!C1 -> ひながた
A2: ④（F）経費を入力する （百万円） | I2: =L16+I24+F13+C43 -> 130.4 | M2: 製作：結城伸太郎
B3: 経費（固定） | E3: 販売促進費 | H3: 人件費 | K3: 事業費
B4: 科目 | C4: 合計 | E4: テナント料 | H4: 科目 | I4: 合計 | K4: 科目 | L4: 合計
B5: 電力費 | E5: 試供品DM費 | H5: 社員給料 | I5: =③給料!E14 -> 32.7 | K5: 事業戦略費
B6: 動力費 | E6: 販売企画費 | H6: 雑給料 | I6: =③給料!J14 -> 1 | K6: 社長戦略費Ａ
B7: ガス光熱費 | E7: 試供品DM費 | H7: 派遣社員費 | I7: =③給料!O14 -> 0 | K7: 社長戦略費Ｂ
B8: 燃料費 | E8: 販売促進費 | H8: 退職金 | K8: 開拓手数料(外交員)
B9: 上水道費 | E9: 広告宣伝費 | F9: 6 | H9: 賞与 | I9: 4 | K9: 消耗資材費 | L9: 4
B10: 下水道費 | E10: 予備 | H10: 通勤手当 | K10: ロイヤリティー
B11: 車輌費 | C11: 2.5 | E11: 予備 | H11: 役員報酬 | I11: 15 | K11: 外注加工費
B12: 家賃地代 | C12: 8 | E12: 予備 | H12: 諸費用 | K12: 運賃荷造費
B13: 賃貸料 | C13: 4.3 | E13: 計 | F13: =SUM(F4:F12) -> 6 | H13: 募集費 | K13: 予備
B14: 研究開発費 | E14: 現状 計 | F14: =SUM(スタート!C37:C42) -> 2 | H14: 教育研修 | K14: 予備
B15: 調査研究費 | H15: 研修費 | K15: 予備
B16: 租税公課 | C16: 2 | H16: 会議費 | K16: 計 | L16: =SUM(L5:L15) -> 4
B17: 接待交際費 | C17: 5 | H17: 福利厚生費 | I17: 6 | K17: 現状 計 | L17: =SUM(スタート!C29:C34) -> 0
B18: 支払手数料 | C18: 5.6 | H18: 法定福利費 | I18: 12
B19: 顧問料 | H19: 予備
B20: リース料 | H20: 予備
B21: 通信交通費 | C21: 1.4 | H21: 予備
B22: 出張費 | H22: 予備
B23: 消耗品費 | C23: 2.3 | H23: 予備
B24: 事務用品費 | C24: 1.5 | H24: 計 | I24: =SUM(I5:I23) -> 70.7
B25: その他経費 | C25: 3.5 | H25: 現状 計 | I25: =SUM(スタート!C12:C28) -> 55.5
B26: 雑費 | C26: 3
B27: 装飾費
B28: 衛生費
B29: 運賃
B30: 荷造包装費
B31: 水道光熱費 | C31: 1.7
B32: 旅費交通費 | C32: 3
B33: 諸会費 | C33: 1.5
B34: 管理諸費
B35: 保守管理費
B36: 図書費 | C36: 0.4
B37: 修繕費 | C37: 1
B38: 修繕維持費
B39: 保険料 | C39: 3
B40: 備品費
...

Sheet ⑤製造原価 (人）
A1: =スタート!C1 -> ひながた
A2: ⑤（V）人件費を入力する（工事職人） | Q2: 製作：結城伸太郎
E3: （百万円） | J3: （百万円） | O3: （百万円）
B4: 人件費明細 | D4: 年収を記入 | G4: 雑給料 | I4: 年収を記入 | L4: 派遣社員 | N4: 年収を記入
B5: 区分・テーブル | C5: 単価 | D5: 人数 | E5: 合計 | G5: 区分・テーブル | H5: 単価 | I5: 人数 | J5: 合計 | L5: 区分・テーブル | M5: 単価 | N5: 人数 | O5: 合計
B6: 社員１ | C6: 4 | D6: 3 | E6: =C6*D6 -> 12 | G6: パート１ | H6: 0 | I6: 0 | J6: =H6*I6 -> 0 | L6: 派遣社員1 | M6: 0 | N6: 0 | O6: =M6*N6 -> 0
B7: 社員２ | C7: 3.5 | D7: 4 | E7: =C7*D7 -> 14 | G7: パート２ | H7: 0 | I7: 0 | J7: =H7*I7 -> 0 | L7: 派遣社員2 | M7: 0 | N7: 0 | O7: =M7*N7 -> 0
B8: 社員３ | C8: 3.1 | D8: 6 | E8: =C8*D8 -> 18.6 | G8: パート３ | H8: 0 | I8: 0 | J8: =H8*I8 -> 0 | L8: 派遣社員3 | M8: 0 | N8: 0 | O8: =M8*N8 -> 0
B9: 社員４ | C9: 0 | D9: 0 | E9: =C9*D9 -> 0 | G9: パート４ | H9: 0 | I9: 0 | J9: =H9*I9 -> 0 | L9: 派遣社員4 | M9: 0 | N9: 0 | O9: =M9*N9 -> 0
B10: 社員５ | C10: 0 | D10: 0 | E10: =C10*D10 -> 0 | G10: パート５ | H10: 0 | I10: 0 | J10: =H10*I10 -> 0 | L10: 派遣社員5 | M10: 0 | N10: 0 | O10: =M10*N10 -> 0
B11: 社員６ | C11: 0 | D11: 0 | E11: =C11*D11 -> 0 | G11: アルバイト１ | H11: 0 | I11: 0 | J11: =H11*I11 -> 0 | L11: 派遣社員6 | M11: 0 | N11: 0 | O11: =M11*N11 -> 0
B12: 社員７ | C12: 0 | D12: 0 | E12: =C12*D12 -> 0 | G12: アルバイト２ | H12: 0 | I12: 0 | J12: =H12*I12 -> 0 | L12: 契約社員１ | M12: 0 | N12: 0 | O12: =M12*N12 -> 0
B13: 社員８ | C13: 0 | D13: 0 | E13: =C13*D13 -> 0 | G13: アルバイト３ | H13: 0 | I13: 0 | J13: =H13*I13 -> 0 | L13: 契約社員２ | M13: 0 | N13: 0 | O13: =M13*N13 -> 0
B14: 社員給料 | C14: 計 | D14: =SUM(D6:D13) -> 13 | E14: =SUM(E6:E13) -> 44.6 | G14: 雑給料 | H14: 計 | I14: =SUM(I6:I13) -> 0 | J14: =SUM(J6:J13) -> 0 | L14: 派遣社員費 | M14: 計 | N14: =SUM(N6:N13) -> 0 | O14: =SUM(O6:O13) -> 0
B15: 給料（現状） | C15: 計 | D15: 9 | E15: =スタート!D60 -> 35 | G15: 給料（現状） | H15: 計 | I15: 0 | J15: =スタート!D61 -> 0 | L15: 給料（現状） | M15: 計 | N15: 0 | O15: =スタート!D62 -> 0
B17: 平均年収 | E17: 上昇率
B18: 未来 | C18: =(E14+J14+O14)/(D14+I14+N14) -> 3.4307692 | D18: 百万円 | E18: =C18/C19 -> 0.8821978
B19: 現状 | C19: =IFERROR((E15+J15+O15)/(N15+I15+D15),"0") -> 3.8888889 | D19: 百万円

Sheet ⑥製造（経費)
A1: =スタート!C1 -> ひながた
A2: ⑥（V）経費を入力する （百万円） | I2: =L20+I16+F13+C43 -> 273.6 | O2: 製作：結城伸太郎
B3: 経費（固定） | E3: 販売促進費 | H3: 人件費 | K3: 事業費
B4: 科目 | C4: 合計 | E4: 販促企画費 | F4: 6 | H4: 科目 | I4: 合計 | K4: 科目 | L4: 合計
B5: 電力費 | E5: 消耗資材費 | H5: 社員給料 | I5: =スタート!D60 -> 35 | K5: 期首商品棚卸高 | O5: 期首商品棚卸高
B6: 動力費 | E6: 広告宣伝費 | H6: 雑給料 | I6: =スタート!D61 -> 0 | K6: 期首製品棚卸高 | L6: 0.2 | O6: 期首製品棚卸高
B7: ガス光熱費 | E7: 募集費 | H7: 派遣社員費 | I7: =スタート!D62 -> 0 | K7: 商品仕入高 | O7: 商品仕入高
B8: 燃料費 | E8: 教育研修 | H8: 賞与 | I8: 4 | K8: 製品仕入高 | O8: 製品仕入高
B9: 上水道費 | E9: 予備 | H9: 福利厚生費 | I9: 6 | K9: 期末商品棚卸高 | M9: （マイナスを入れてから入力） | O9: 期末商品棚卸高 | P9: 0.2
B10: 下水道費 | E10: 予備 | H10: 法定福利費 | I10: 13 | K10: 期末製品棚卸高 | L10: -5 | M10: （マイナスを入れてから入力） | O10: 期末製品棚卸高 | P10: -5
B11: 車輌費 | C11: 6.9 | E11: 予備 | H11: 通勤手当 | K11: 期首原材料棚卸高 | O11: 期首原材料棚卸高
B12: 家賃地代 | C12: 2 | E12: 予備 | H12: 予備 | K12: 原材料仕入高１ | L12: 58 | O12: 原材料仕入高１ | P12: 58
B13: 賃貸料 | E13: 計 | F13: =SUM(F4:F12) -> 6 | H13: 予備 | K13: 原材料仕入高２ | O13: 原材料仕入高２
B14: 研究開発費 | E14: 現状 計 | F14: =SUM(スタート!D35:D42) -> 0 | H14: 予備 | K14: 原材料仕入高３ | O14: 原材料仕入高３
B15: 調査研究費 | H15: その他 | K15: 仕掛品 | O15: 仕掛品
B16: 租税公課 | H16: 計 | I16: =SUM(I5:I15) -> 58 | K16: 期末原材料棚卸高 | O16: 期末原材料棚卸高
B17: 接待交際費 | H17: 現状 計 | I17: =SUM(スタート!D13:D28)+SUM(スタート!D60:D62) -> 55 | K17: 在庫 | O17: 在庫
B18: 支払手数料 | K18: 外注 | L18: 140 | O18: 外注
B19: 顧問料 | K19: 外注加工費 | O19: 外注加工費
B20: リース料 | K20: 計 | L20: =SUM(L5:L19) -> 193.2
B21: 通信交通費 | K21: 現状 計 | L21: =SUM(スタート!D43:D56) -> 156.5
B22: 出張費
B23: 消耗品費
B24: 事務用品費
B25: その他経費 | C25: 3.5
B26: 雑費 | C26: 4
B27: 装飾費
B28: 衛生費
B29: 運賃
B30: 荷造包装費
B31: 水道光熱費
B32: 旅費交通費
B33: 諸会費
B34: 管理諸費
B35: 保守管理費
B36: 図書費
B37: 修繕費
B38: 修繕維持費
... B42: 減価償却費
B43: 計 | C43: =SUM(C5:C42) -> 16.4
...

Sheet ⑦原価詳細
A1: =スタート!C1 -> ひながた
A2: ⑦（PQ）原価の詳細 | F2: 売上計 | G2: =F31 -> 450000000 | K2: 製作：結城伸太郎
C4: ↓②～④に順番に記入
A5: ① | C5: ④ | D5: ③ | E5: ②
B6: 粗利益額 | C6: 1個あたり粗利益 | D6: 数量 | E6: 単価 | F6: 売上 | G6: 粗利益率
A7: 商品名 | B7: 円 | C7: １円 | D7: 個 | E7: １円 | F7: 円
A8: 塗装工事 | B8: =D8*C8 -> 129500000 | C8: 370000 | D8: 350 | E8: 1000000 | F8: =D8*E8 -> 350000000 | G8: =IFERROR(C8/E8,"0") -> 0.37
A9: リフォーム工事 | B9: =D9*C9 -> 17400000 | C9: 120000 | D9: 145 | E9: 340000 | F9: =D9*E9 -> 49300000 | G9: =IFERROR(C9/E9,"0") -> 0.35294118
A10: 小工事 | B10: =D10*C10 -> 2509990 | C10: 21826 | D10: 115 | E10: 50000 | F10: =D10*E10 -> 5750000 | G10: =IFERROR(C10/E10,"0") -> 0.43652
A11: 板金工事 | B11: =D11*C11 -> 26985500 | C11: 174100 | D11: 155 | E11: 290000 | F11: =D11*E11 -> 44950000 | G11: =IFERROR(C11/E11,"0") -> 0.60034483
A12: ○○ | B12: =D12*C12 -> 0 | F12: =D12*E12 -> 0 | G12: =IFERROR(C12/E12,"0") -> 0
A13: ○○ | B13: =D13*C13 -> 0 | F13: =D13*E13 -> 0 | G13: =IFERROR(C13/E13,"0") -> 0
A14: ○○ | B14: =D14*C14 -> 0 | F14: =D14*E14 -> 0 | G14: =IFERROR(C14/E14,"0") -> 0
A15: ○○ | B15: =D15*C15 -> 0 | F15: =D15*E15 -> 0 | G15: =IFERROR(C15/E15,"0") -> 0
A16: 〇〇 | B16: =D16*C16 -> 0 | F16: =D16*E16 -> 0 | G16: =IFERROR(C16/E16,"0") -> 0
A17: ○○ | B17: =D17*C17 -> 0 | F17: =D17*E17 -> 0 | G17: =IFERROR(C17/E17,"0") -> 0
A18: ○○ | B18: =D18*C18 -> 0 | F18: =D18*E18 -> 0 | G18: =IFERROR(C18/E18,"0") -> 0
A19: ○○ | B19: =D19*C19 -> 0 | F19: =D19*E19 -> 0 | G19: =IFERROR(C19/E19,"0") -> 0
A20: ○○ | B20: =D20*C20 -> 0 | F20: =D20*E20 -> 0 | G20: =IFERROR(C20/E20,"0") -> 0
A21: ○○ | B21: =D21*C21 -> 0 | F21: =D21*E21 -> 0 | G21: =IFERROR(C21/E21,"0") -> 0
A22: ○○ | B22: =D22*C22 -> 0 | F22: =D22*E22 -> 0 | G22: =IFERROR(C22/E22,"0") -> 0
A23: ○○ | B23: =D23*C23 -> 0 | F23: =D23*E23 -> 0 | G23: =IFERROR(C23/E23,"0") -> 0
... A29: その他群 | B29: =D29*C29 -> 0 | F29: =D29*E29 -> 0 | G29: =IFERROR(C29/E29,"0") -> 0
B30: M（計） | C30: M(個） | D30: 数量（Q) | E30: 平均客単価 | F30: 売上 計 | G30: 平均粗利
A31: 実績 | B31: =SUM(B8:B29) -> 176395490 | C31: =AVERAGE(C8:C29,"0") -> 137185.2 | D31: =SUM(D8:D29) -> 765 | E31: =IFERROR(F31/D31,"") -> 588235.29 | F31: =SUM(F8:F29) -> 450000000 | G31: =AVERAGE(G8:G29) -> 0.4399515
A33: ０になるまで修正 | C33: 粗利益率(%) | D33: 客数(月) | E33: 客単価(円) | F33: 戦力（人） | G33: =③給料!D14+③給料!I14+③給料!N14+'⑤製造原価 (人）'!D14+'⑤製造原価 (人）'!I14+'⑤製造原価 (人）'!N14 -> 25
A34: └→不足額 | B34: ='②⑧MQ（未来）'!F17*1000 -> -4.51 | C34: =IFERROR(B31/F31,"") -> 0.39198998 | F34: 1人あたりの利益 | G34: １人あたりの生産性
C35: 計画との差 | D35: 戦力（1人当たりの利益力 | E35: 1人当たり生産性
A36: 粗利益額 | B36: =B31 -> 176395490 | C36: 0 | E36: 0 | F36: =B36/G33 -> 7055819.6 | G36: =F31/G33 -> 18000000

Sheet 損益分岐点
A1: 来期 | D1: 現状
A2: 売上高 | B2: =⑦原価詳細!F31 -> 450000000 | D2: 売上高 | E2: =スタート!C6*1000000 -> 355000000 | H2: 売上高 | I2: 総費用 | J2: 利益 | K2: 利益 | L2: 損失 | N2: 売上高 | O2: 総費用 | P2: 利益 | Q2: 利益 | R2: 損失
A3: 変動費 | B3: ='⑥製造（経費)'!I2*1000000 -> 2.736e+08 | D3: 変動費 | E3: =スタート!G102*1000000 -> 224900000 | H3: 0 | I3: =B4 -> 130400000 | J3: =H3-I3 -> -130400000 | K3: =IF(J3>0, J3, NA()) -> #N/A | L3: =IF(J3<0, J3, NA()) -> -130400000 | N3: 0 | O3: =E4 -> 103800000 | P3: =N3-O3 -> -103800000 | Q3: =IF(P3>0, P3, NA()) -> #N/A | R3: =IF(P3<0, P3, NA()) -> -103800000
A4: 固定費 | B4: =④経費!I2*1000000 -> 130400000 | D4: 固定費 | E4: =スタート!G103*1000000 -> 103800000 | H4: =B2/6 -> 75000000 | I4: =(B4+(B3/B2)*H4) -> 176000000 | J4: =H4-I4 -> -101000000 | K4: =IF(J4>0, J4, NA()) -> #N/A | L4: =IF(J4<0, J4, NA()) -> -101000000 | N4: =E2/6 -> 59166667 | O4: =(E4+(E3/E2)*N4) -> 1.4128333e+08 | P4: =N4-O4 -> -82116667 | Q4: =IF(P4>0, P4, NA()) -> #N/A | R4: =IF(P4<0, P4, NA()) -> -82116667
A5: 変動率（変動費÷売上高） | B5: =B3/B2 -> 0.608 | D5: 変動率（変動費÷売上高） | E5: =E3/E2 -> 0.63352113 | H5: =B2/3 -> 150000000 | I5: =(B4+(B3/B2)*H5) -> 221600000 | J5: =H5-I5 -> -71600000 | K5: =IF(J5>0, J5, NA()) -> #N/A | L5: =IF(J5<0, J5, NA()) -> -71600000 | N5: =E2/3 -> 1.1833333e+08 | O5: =(E4+(E3/E2)*N5) -> 1.7876667e+08 | P5: =N5-O5 -> -60433333 | Q5: =IF(P5>0, P5, NA()) -> #N/A | R5: =IF(P5<0, P5, NA()) -> -60433333
A6: 損益分岐点 固定費÷(1-変動率) | B6: =B4/(1-B3/B2) -> 3.3265306e+08 | D6: 損益分岐点 固定費÷(1-変動率) | E6: =E4/(1-E3/E2) -> 2.8323597e+08 | H6: =B2/2 -> 225000000 | I6: =(B4+(B3/B2)*H6) -> 2.672e+08 | J6: =H6-I6 -> -42200000 | K6: =IF(J6>0, J6, NA()) -> #N/A | L6: =IF(J6<0, J6, NA()) -> -42200000 | N6: =E2/2 -> 177500000 | O6: =(E4+(E3/E2)*N6) -> 216250000 | P6: =N6-O6 -> -38750000 | Q6: =IF(P6>0, P6, NA()) -> #N/A | R6: =IF(P6<0, P6, NA()) -> -38750000
H7: =2*B2/3 -> 300000000 | I7: =(B4+(B3/B2)*H7) -> 312800000 | J7: =H7-I7 -> -12800000 | K7: =IF(J7>0, J7, NA()) -> #N/A | L7: =IF(J7<0, J7, NA()) -> -12800000 | N7: =2*E2/3 -> 2.3666667e+08 | O7: =(E4+(E3/E2)*N7) -> 2.5373333e+08 | P7: =N7-O7 -> -17066667 | Q7: =IF(P7>0, P7, NA()) -> #N/A | R7: =IF(P7<0, P7, NA()) -> -17066667
H8: =5*B2/6 -> 375000000 | I8: =(B4+(B3/B2)*H8) -> 3.584e+08 | J8: =H8-I8 -> 16600000 | K8: =IF(J8>0, J8, NA()) -> 16600000 | L8: =IF(J8<0, J8, NA()) -> #N/A | N8: =5*E2/6 -> 2.9583333e+08 | O8: =(E4+(E3/E2)*N8) -> 2.9121667e+08 | P8: =N8-O8 -> 4616666.7 | Q8: =IF(P8>0, P8, NA()) -> 4616666.7 | R8: =IF(P8<0, P8, NA()) -> #N/A
H9: =B2 -> 450000000 | I9: =(B4+(B3/B2)*H9) -> 4.04e+08 | J9: =H9-I9 -> 46000000 | K9: =IF(J9>0, J9, NA()) -> 46000000 | L9: =IF(J9<0, J9, NA()) -> #N/A | N9: =E2 -> 355000000 | O9: =(E4+(E3/E2)*N9) -> 328700000 | P9: =N9-O9 -> 26300000 | Q9: =IF(P9>0, P9, NA()) -> 26300000 | R9: =IF(P9<0, P9, NA()) -> #N/A
A29: 製作：結城伸太郎

Sheet 進捗実績値入力シート
B1: =スタート!C1 -> ひながた
B2: =スタート!G1 -> 4 | C2: 期短期計画 | D2: 45536 | E2: 更新 | K2: 目標売上成長率 | L2: =C6/C5 -> 1.2676056 | S2: 製作：結城伸太郎
B3: 決算目標 | C3: ='②⑧MQ（未来）'!B3*1000 -> 450000 | F3: 経費内訳 | K3: 製造原価内訳
C4: 目標 | D4: 実績｜累積 | F4: 事業費 | K4: 事業費 | P4: 経費（固定）
B5: 直近売上 | C5: ='MQ（現状）'!B3 -> 355 | F5: 科目 | G5: 目標 | H5: 実績｜累積 | K5: 科目 | L5: 目標 | M5: 実績｜累積 | P5: 科目 | Q5: 目標 | R5: 実績｜累積
B6: 目標売上 | C6: ='②⑧MQ（未来）'!B3 -> 450 | F6: =④経費!K5 -> 事業戦略費 | G6: =④経費!L5 -> 0 | K6: ='⑥製造（経費)'!K5 -> 期首商品棚卸高 | L6: ='⑥製造（経費)'!L5 -> 0 | P6: ='⑥製造（経費)'!B5 -> 電力費 | Q6: ='⑥製造（経費)'!C5 -> 0
B7: 売上総利益 | C7: ='②⑧MQ（未来）'!F13 -> 176.4 | F7: =④経費!K6 -> 社長戦略費Ａ | G7: =④経費!L6 -> 0 | K7: ='⑥製造（経費)'!K6 -> 期首製品棚卸高 | L7: ='⑥製造（経費)'!L6 -> 0.2 | P7: ='⑥製造（経費)'!B6 -> 動力費 | Q7: ='⑥製造（経費)'!C6 -> 0
B8: 粗利益率(%) | C8: =IFERROR('②⑧MQ（未来）'!G16,"") -> 0.392 | F8: =④経費!K7 -> 社長戦略費Ｂ | G8: =④経費!L7 -> 0 | K8: ='⑥製造（経費)'!K7 -> 商品仕入高 | L8: ='⑥製造（経費)'!L7 -> 0 | P8: ='⑥製造（経費)'!B7 -> ガス光熱費 | Q8: ='⑥製造（経費)'!C7 -> 0
B9: 製造原価 | C9: =L21+L35+L46+Q44 -> 273.6 | F9: =④経費!K8 -> 開拓手数料(外交員) | G9: =④経費!L8 -> 0 | K9: ='⑥製造（経費)'!K8 -> 製品仕入高 | L9: ='⑥製造（経費)'!L8 -> 0 | P9: ='⑥製造（経費)'!B8 -> 燃料費 | Q9: ='⑥製造（経費)'!C8 -> 0
B10: 固定費 | C10: =C11+C12 -> 130.4 | F10: =④経費!K9 -> 消耗資材費 | G10: =④経費!L9 -> 4 | K10: ='⑥製造（経費)'!K9 -> 期末商品棚卸高 | L10: ='⑥製造（経費)'!L9 -> 0 | P10: ='⑥製造（経費)'!B9 -> 上水道費 | Q10: ='⑥製造（経費)'!C9 -> 0
B11: （経費） | C11: =C61+G39+G17 -> 124.4 | F11: =④経費!K10 -> ロイヤリティー | G11: =④経費!L10 -> 0 | K11: ='⑥製造（経費)'!K10 -> 期末製品棚卸高 | L11: ='⑥製造（経費)'!L10 -> -5 | P11: ='⑥製造（経費)'!B10 -> 下水道費 | Q11: ='⑥製造（経費)'!C10 -> 0
B12: （販促費） | C12: =G50 -> 6 | F12: =④経費!K11 -> 外注加工費 | G12: =④経費!L11 -> 0 | K12: ='⑥製造（経費)'!K11 -> 期首原材料棚卸高 | L12: ='⑥製造（経費)'!L11 -> 0 | P12: ='⑥製造（経費)'!B11 -> 車輌費 | Q12: ='⑥製造（経費)'!C11 -> 6.9
B13: 営業利益 | C13: =C6-C9-C10 -> 46 | F13: =④経費!K12 -> 運賃荷造費 | G13: =④経費!L12 -> 0 | K13: ='⑥製造（経費)'!K12 -> 原材料仕入高１ | L13: ='⑥製造（経費)'!L12 -> 58 | P13: ='⑥製造（経費)'!B12 -> 家賃地代 | Q13: ='⑥製造（経費)'!C12 -> 2
B14: 営業外収益 | C14: =①利益!B4 -> 10 | F14: =④経費!K13 -> 予備 | G14: =④経費!L13 -> 0 | K14: ='⑥製造（経費)'!K13 -> 原材料仕入高２ | L14: ='⑥製造（経費)'!L13 -> 0 | P14: ='⑥製造（経費)'!B13 -> 賃貸料 | Q14: ='⑥製造（経費)'!C13 -> 0
B15: 営業外費用 | C15: =①利益!B5 -> 0 | F15: =④経費!K14 -> 予備 | G15: =④経費!L14 -> 0 | K15: ='⑥製造（経費)'!K14 -> 原材料仕入高３ | L15: ='⑥製造（経費)'!L14 -> 0 | P15: ='⑥製造（経費)'!B14 -> 研究開発費 | Q15: ='⑥製造（経費)'!C14 -> 0
B16: 経常利益 | C16: =C13+C14-C15 -> 56 | F16: =④経費!K15 -> 予備 | G16: =④経費!L15 -> 0 | K16: ='⑥製造（経費)'!K15 -> 仕掛品 | L16: ='⑥製造（経費)'!L15 -> 0 | P16: ='⑥製造（経費)'!B15 -> 調査研究費 | Q16: ='⑥製造（経費)'!C15 -> 0
B17: 特別利益 | C17: =①利益!I3 -> 10 | F17: 計 | G17: =SUM(G6:G16) -> 4 | H17: =SUM(H6:H16) -> 0 | K17: ='⑥製造（経費)'!K16 -> 期末原材料棚卸高 | L17: ='⑥製造（経費)'!L16 -> 0 | P17: ='⑥製造（経費)'!B16 -> 租税公課 | Q17: ='⑥製造（経費)'!C16 -> 0
B18: 特別損失 | C18: =①利益!I4 -> 0 | F18: 人件費内訳 | K18: ='⑥製造（経費)'!K17 -> 在庫 | L18: ='⑥製造（経費)'!L17 -> 0 | P18: ='⑥製造（経費)'!B17 -> 接待交際費 | Q18: ='⑥製造（経費)'!C17 -> 0
B19: 純利益 | C19: =C16+C17-C18 -> 66 | F19: 科目 | G19: 目標 | H19: 実績｜累積 | K19: ='⑥製造（経費)'!K18 -> 外注 | L19: ='⑥製造（経費)'!L18 -> 140 | P19: ='⑥製造（経費)'!B18 -> 支払手数料 | Q19: ='⑥製造（経費)'!C18 -> 0
B20: 税引き前利益 | C20: =C19 -> 66 | D20: =D19 -> 0 | F20: =④経費!H5 -> 社員給料 | G20: =④経費!I5 -> 32.7 | K20: ='⑥製造（経費)'!K19 -> 外注加工費 | L20: ='⑥製造（経費)'!L19 -> 0 | P20: ='⑥製造（経費)'!B19 -> 顧問料 | Q20: ='⑥製造（経費)'!C19 -> 0
B21: 経費（固定） | F21: =④経費!H6 -> 雑給料 | G21: =④経費!I6 -> 1 | K21: 計 | L21: =SUM(L6:L20) -> 193.2 | M21: =SUM(M10:M20) -> 0 | P21: ='⑥製造（経費)'!B20 -> リース料 | Q21: ='⑥製造（経費)'!C20 -> 0
B22: 科目 | C22: 目標 | F22: =④経費!H7 -> 派遣社員費 | G22: =④経費!I7 -> 0 | K22: 人件費 | P22: ='⑥製造（経費)'!B21 -> 通信交通費 | Q22: ='⑥製造（経費)'!C21 -> 0
B23: =④経費!B5 -> 電力費 | C23: =④経費!C5 -> 0 | F23: =④経費!H8 -> 退職金 | G23: =④経費!I8 -> 0 | K23: 科目 | L23: 目標 | M23: 合計 | P23: ='⑥製造（経費)'!B22 -> 出張費 | Q23: ='⑥製造（経費)'!C22 -> 0
B24: =④経費!B6 -> 動力費 | C24: =④経費!C6 -> 0 | F24: =④経費!H9 -> 賞与 | G24: =④経費!I9 -> 4 | K24: ='⑥製造（経費)'!H5 -> 社員給料 | L24: ='⑥製造（経費)'!I5 -> 35 | P24: ='⑥製造（経費)'!B23 -> 消耗品費 | Q24: ='⑥製造（経費)'!C23 -> 0
B25: =④経費!B7 -> ガス光熱費 | C25: =④経費!C7 -> 0 | F25: =④経費!H10 -> 通勤手当 | G25: =④経費!I10 -> 0 | K25: ='⑥製造（経費)'!H6 -> 雑給料 | L25: ='⑥製造（経費)'!I6 -> 0 | P25: ='⑥製造（経費)'!B24 -> 事務用品費 | Q25: ='⑥製造（経費)'!C24 -> 0
B26: =④経費!B8 -> 燃料費 | C26: =④経費!C8 -> 0 | F26: =④経費!H11 -> 役員報酬 | G26: =④経費!I11 -> 15 | K26: ='⑥製造（経費)'!H7 -> 派遣社員費 | L26: ='⑥製造（経費)'!I7 -> 0 | P26: ='⑥製造（経費)'!B25 -> その他経費 | Q26: ='⑥製造（経費)'!C25 -> 3.5
B27: =④経費!B9 -> 上水道費 | C27: =④経費!C9 -> 0 | F27: =④経費!H12 -> 諸費用 | G27: =④経費!I12 -> 0 | K27: ='⑥製造（経費)'!H8 -> 賞与 | L27: ='⑥製造（経費)'!I8 -> 4 | P27: ='⑥製造（経費)'!B26 -> 雑費 | Q27: ='⑥製造（経費)'!C26 -> 4
B28: =④経費!B10 -> 下水道費 | C28: =④経費!C10 -> 0 | F28: =④経費!H13 -> 募集費 | G28: =④経費!I13 -> 0 | K28: ='⑥製造（経費)'!H9 -> 福利厚生費 | L28: ='⑥製造（経費)'!I9 -> 6 | P28: ='⑥製造（経費)'!B27 -> 装飾費 | Q28: ='⑥製造（経費)'!C27 -> 0
B29: =④経費!B11 -> 車輌費 | C29: =④経費!C11 -> 2.5 | F29: =④経費!H14 -> 教育研修 | G29: =④経費!I14 -> 0 | K29: ='⑥製造（経費)'!H10 -> 法定福利費 | L29: ='⑥製造（経費)'!I10 -> 13 | P29: ='⑥製造（経費)'!B28 -> 衛生費 | Q29: ='⑥製造（経費)'!C28 -> 0
B30: =④経費!B12 -> 家賃地代 | C30: =④経費!C12 -> 8 | F30: =④経費!H15 -> 研修費 | G30: =④経費!I15 -> 0 | K30: ='⑥製造（経費)'!H11 -> 通勤手当 | L30: ='⑥製造（経費)'!I11 -> 0 | P30: ='⑥製造（経費)'!B29 -> 運賃 | Q30: ='⑥製造（経費)'!C29 -> 0
B31: =④経費!B13 -> 賃貸料 | C31: =④経費!C13 -> 4.3 | F31: =④経費!H16 -> 会議費 | G31: =④経費!I16 -> 0 | K31: ='⑥製造（経費)'!H12 -> 予備 | L31: ='⑥製造（経費)'!I12 -> 0 | P31: ='⑥製造（経費)'!B30 -> 荷造包装費 | Q31: ='⑥製造（経費)'!C30 -> 0
B32: =④経費!B14 -> 研究開発費 | C32: =④経費!C14 -> 0 | F32: =④経費!H17 -> 福利厚生費 | G32: =④経費!I17 -> 6 | K32: ='⑥製造（経費)'!H13 -> 予備 | L32: ='⑥製造（経費)'!I13 -> 0 | P32: ='⑥製造（経費)'!B31 -> 水道光熱費 | Q32: ='⑥製造（経費)'!C31 -> 0
B33: =④経費!B15 -> 調査研究費 | C33: =④経費!C15 -> 0 | F33: =④経費!H18 -> 法定福利費 | G33: =④経費!I18 -> 12 | K33: ='⑥製造（経費)'!H14 -> 予備 | L33: ='⑥製造（経費)'!I14 -> 0 | P33: ='⑥製造（経費)'!B32 -> 旅費交通費 | Q33: ='⑥製造（経費)'!C32 -> 0
B34: =④経費!B16 -> 租税公課 | C34: =④経費!C16 -> 2 | F34: =④経費!H19 -> 予備 | G34: =④経費!I19 -> 0 | K34: ='⑥製造（経費)'!H15 -> その他 | L34: ='⑥製造（経費)'!I15 -> 0 | P34: ='⑥製造（経費)'!B33 -> 諸会費 | Q34: ='⑥製造（経費)'!C33 -> 0
B35: =④経費!B17 -> 接待交際費 | C35: =④経費!C17 -> 5 | F35: =④経費!H20 -> 予備 | G35: =④経費!I20 -> 0 | K35: 計 | L35: =SUM(L24:L34) -> 58 | M35: =SUM(M24:M34) -> 0 | P35: ='⑥製造（経費)'!B34 -> 管理諸費 | Q35: ='⑥製造（経費)'!C34 -> 0
B36: =④経費!B18 -> 支払手数料 | C36: =④経費!C18 -> 5.6 | F36: =④経費!H21 -> 予備 | G36: =④経費!I21 -> 0 | K36: 販売促進費 | L36: 目標 | P36: ='⑥製造（経費)'!B35 -> 保守管理費 | Q36: ='⑥製造（経費)'!C35 -> 0
B37: =④経費!B19 -> 顧問料 | C37: =④経費!C19 -> 0 | F37: =④経費!H22 -> 予備 | G37: =④経費!I22 -> 0 | K37: ='⑥製造（経費)'!E4 -> 販促企画費 | L37: ='⑥製造（経費)'!F4 -> 6 | P37: ='⑥製造（経費)'!B36 -> 図書費 | Q37: ='⑥製造（経費)'!C36 -> 0
B38: =④経費!B20 -> リース料 | C38: =④経費!C20 -> 0 | F38: =④経費!H23 -> 予備 | G38: =④経費!I23 -> 0 | K38: ='⑥製造（経費)'!E5 -> 消耗資材費 | L38: ='⑥製造（経費)'!F5 -> 0 | P38: ='⑥製造（経費)'!B37 -> 修繕費 | Q38: ='⑥製造（経費)'!C37 -> 0
B39: =④経費!B21 -> 通信交通費 | C39: =④経費!C21 -> 1.4 | F39: 計 | G39: =SUM(G20:G38) -> 70.7 | H39: =SUM(H30:H38) -> 0 | K39: ='⑥製造（経費)'!E6 -> 広告宣伝費 | L39: ='⑥製造（経費)'!F6 -> 0 | P39: ='⑥製造（経費)'!B38 -> 修繕維持費 | Q39: ='⑥製造（経費)'!C38 -> 0
B40: =④経費!B22 -> 出張費 | C40: =④経費!C22 -> 0 | F40: 販売促進費 | G40: 目標 | H40: 実績｜累積 | K40: ='⑥製造（経費)'!E7 -> 募集費 | L40: ='⑥製造（経費)'!F7 -> 0 | P40: ='⑥製造（経費)'!B39 -> 保険料 | Q40: ='⑥製造（経費)'!C39 -> 0
...

Sheet 部門別販売計画
A1: 商品名 | B1: 売上目標 | D1: =進捗実績値入力シート!D2 -> 45536 | F1: =TEXT(EDATE($D$1,1),"m")&"月" -> 10月 | H1: =TEXT(EDATE($D$1,2),"m")&"月" -> 11月 | J1: =TEXT(EDATE($D$1,3),"m")&"月" -> 12月 | L1: =TEXT(EDATE($D$1,4),"m")&"月" -> 1月 | N1: =TEXT(EDATE($D$1,5),"m")&"月" -> 2月 | P1: =TEXT(EDATE($D$1,6),"m")&"月" -> 3月 | R1: =TEXT(EDATE($D$1,7),"m")&"月" -> 4月 | T1: =TEXT(EDATE($D$1,8),"m")&"月" -> 5月 | V1: =TEXT(EDATE($D$1,9),"m")&"月" -> 6月 | X1: =TEXT(EDATE($D$1,10),"m")&"月" -> 7月 | Z1: =TEXT(EDATE($D$1,11),"m")&"月" -> 8月
B2: =⑦原価詳細!G2 -> 450000000 | D2: 当月 | E2: 累計 | F2: 当月 | G2: 累計 | H2: 当月 | I2: 累計 | J2: 当月 | K2: 累計 | L2: 当月 | M2: 累計 | N2: 当月 | O2: 累計 | P2: 当月 | Q2: 累計 | R2: 当月 | S2: 累計 | T2: 当月 | U2: 累計 | V2: 当月 | W2: 累計 | X2: 当月 | Y2: 累計 | Z2: 当月 | AA2: 累計 | AB2: 製作：結城伸太郎
A3: =⑦原価詳細!A8 -> 塗装工事 | B3: =⑦原価詳細!F8/1000000 -> 350 | C3: 目標 | E3: =D3 -> 0 | G3: =E3+F3 -> 0 | I3: =G3+H3 -> 0 | K3: =I3+J3 -> 0 | M3: =K3+L3 -> 0 | O3: =M3+N3 -> 0 | Q3: =O3+P3 -> 0 | S3: =Q3+R3 -> 0 | U3: =S3+T3 -> 0 | W3: =U3+V3 -> 0 | Y3: =W3+X3 -> 0 | AA3: =Y3+Z3 -> 0
B4: =B3-D3-F3-H3-J3-L3-N3-P3-R3-T3-V3-X3-Z3 -> 350 | C4: 実績 | E4: =D4 -> 0 | G4: =E4+F4 -> 0 | I4: =G4+H4 -> 0 | K4: =I4+J4 -> 0 | M4: =K4+L4 -> 0 | O4: =M4+N4 -> 0 | Q4: =O4+P4 -> 0 | S4: =Q4+R4 -> 0 | U4: =S4+T4 -> 0 | W4: =U4+V4 -> 0 | Y4: =W4+X4 -> 0 | AA4: =Y4+Z4 -> 0
A5: =⑦原価詳細!A9 -> リフォーム工事 | B5: =⑦原価詳細!F9/1000000 -> 49.3 | C5: 目標 | E5: =D5 -> 0 | G5: =E5+F5 -> 0 | I5: =G5+H5 -> 0 | K5: =I5+J5 -> 0 | M5: =K5+L5 -> 0 | O5: =M5+N5 -> 0 | Q5: =O5+P5 -> 0 | S5: =Q5+R5 -> 0 | U5: =S5+T5 -> 0 | W5: =U5+V5 -> 0 | Y5: =W5+X5 -> 0 | AA5: =Y5+Z5 -> 0
B6: =B5-D5-F5-H5-J5-L5-N5-P5-R5-T5-V5-X5-Z5 -> 49.3 | C6: 実績 | E6: =D6 -> 0 | G6: =E6+F6 -> 0 | I6: =G6+H6 -> 0 | K6: =I6+J6 -> 0 | M6: =K6+L6 -> 0 | O6: =M6+N6 -> 0 | Q6: =O6+P6 -> 0 | S6: =Q6+R6 -> 0 | U6: =S6+T6 -> 0 | W6: =U6+V6 -> 0 | Y6: =W6+X6 -> 0 | AA6: =Y6+Z6 -> 0
A7: =⑦原価詳細!A10 -> 小工事 | B7: =⑦原価詳細!F10/1000000 -> 5.75 | C7: 目標 | E7: =D7 -> 0 | G7: =E7+F7 -> 0 | I7: =G7+H7 -> 0 | K7: =I7+J7 -> 0 | M7: =K7+L7 -> 0 | O7: =M7+N7 -> 0 | Q7: =O7+P7 -> 0 | S7: =Q7+R7 -> 0 | U7: =S7+T7 -> 0 | W7: =U7+V7 -> 0 | Y7: =W7+X7 -> 0 | AA7: =Y7+Z7 -> 0
B8: =B7-D7-F7-H7-J7-L7-N7-P7-R7-T7-V7-X7-Z7 -> 5.75 | C8: 実績 | E8: =D8 -> 0 | G8: =E8+F8 -> 0 | I8: =G8+H8 -> 0 | K8: =I8+J8 -> 0 | M8: =K8+L8 -> 0 | O8: =M8+N8 -> 0 | Q8: =O8+P8 -> 0 | S8: =Q8+R8 -> 0 | U8: =S8+T8 -> 0 | W8: =U8+V8 -> 0 | Y8: =W8+X8 -> 0 | AA8: =Y8+Z8 -> 0
A9: =⑦原価詳細!A11 -> 板金工事 | B9: =⑦原価詳細!F11/1000000 -> 44.95 | C9: 目標 | E9: =D9 -> 0 | G9: =E9+F9 -> 0 | I9: =G9+H9 -> 0 | K9: =I9+J9 -> 0 | M9: =K9+L9 -> 0 | O9: =M9+N9 -> 0 | Q9: =O9+P9 -> 0 | S9: =Q9+R9 -> 0 | U9: =S9+T9 -> 0 | W9: =U9+V9 -> 0 | Y9: =W9+X9 -> 0 | AA9: =Y9+Z9 -> 0
B10: =B9-D9-F9-H9-J9-L9-N9-P9-R9-T9-V9-X9-Z9 -> 44.95 | C10: 実績 | E10: =D10 -> 0 | G10: =E10+F10 -> 0 | I10: =G10+H10 -> 0 | K10: =I10+J10 -> 0 | M10: =K10+L10 -> 0 | O10: =M10+N10 -> 0 | Q10: =O10+P10 -> 0 | S10: =Q10+R10 -> 0 | U10: =S10+T10 -> 0 | W10: =U10+V10 -> 0 | Y10: =W10+X10 -> 0 | AA10: =Y10+Z10 -> 0
A11: =⑦原価詳細!A12 -> ○○ | B11: =⑦原価詳細!F12/1000000 -> 0 | C11: 目標 | E11: =D11 -> 0 | G11: =E11+F11 -> 0 | I11: =G11+H11 -> 0 | K11: =I11+J11 -> 0 | M11: =K11+L11 -> 0 | O11: =M11+N11 -> 0 | Q11: =O11+P11 -> 0 | S11: =Q11+R11 -> 0 | U11: =S11+T11 -> 0 | W11: =U11+V11 -> 0 | Y11: =W11+X11 -> 0 | AA11: =Y11+Z11 -> 0
B12: =B11-D11-F11-H11-J11-L11-N11-P11-R11-T11-V11-X11-Z11 -> 0 | C12: 実績 | E12: =D12 -> 0 | G12: =E12+F12 -> 0 | I12: =G12+H12 -> 0 | K12: =I12+J12 -> 0 | M12: =K12+L12 -> 0 | O12: =M12+N12 -> 0 | Q12: =O12+P12 -> 0 | S12: =Q12+R12 -> 0 | U12: =S12+T12 -> 0 | W12: =U12+V12 -> 0 | Y12: =W12+X12 -> 0 | AA12: =Y12+Z12 -> 0
A13: =⑦原価詳細!A13 -> ○○ | B13: =⑦原価詳細!F13/1000000 -> 0 | C13: 目標 | E13: =D13 -> 0 | G13: =E13+F13 -> 0 | I13: =G13+H13 -> 0 | K13: =I13+J13 -> 0 | M13: =K13+L13 -> 0 | O13: =M13+N13 -> 0 | Q13: =O13+P13 -> 0 | S13: =Q13+R13 -> 0 | U13: =S13+T13 -> 0 | W13: =U13+V13 -> 0 | Y13: =W13+X13 -> 0 | AA13: =Y13+Z13 -> 0
B14: =B13-D13-F13-H13-J13-L13-N13-P13-R13-T13-V13-X13-Z13 -> 0 | C14: 実績 | E14: =D14 -> 0 | G14: =E14+F14 -> 0 | I14: =G14+H14 -> 0 | K14: =I14+J14 -> 0 | M14: =K14+L14 -> 0 | O14: =M14+N14 -> 0 | Q14: =O14+P14 -> 0 | S14: =Q14+R14 -> 0 | U14: =S14+T14 -> 0 | W14: =U14+V14 -> 0 | Y14: =W14+X14 -> 0 | AA14: =Y14+Z14 -> 0
A15: =⑦原価詳細!A14 -> ○○ | B15: =⑦原価詳細!F14/1000000 -> 0 | C15: 目標 | E15: =D15 -> 0 | G15: =E15+F15 -> 0 | I15: =G15+H15 -> 0 | K15: =I15+J15 -> 0 | M15: =K15+L15 -> 0 | O15: =M15+N15 -> 0 | Q15: =O15+P15 -> 0 | S15: =Q15+R15 -> 0 | U15: =S15+T15 -> 0 | W15: =U15+V15 -> 0 | Y15: =W15+X15 -> 0 | AA15: =Y15+Z15 -> 0
B16: =B15-D15-F15-H15-J15-L15-N15-P15-R15-T15-V15-X15-Z15 -> 0 | C16: 実績 | E16: =D16 -> 0 | G16: =E16+F16 -> 0 | I16: =G16+H16 -> 0 | K16: =I16+J16 -> 0 | M16: =K16+L16 -> 0 | O16: =M16+N16 -> 0 | Q16: =O16+P16 -> 0 | S16: =Q16+R16 -> 0 | U16: =S16+T16 -> 0 | W16: =U16+V16 -> 0 | Y16: =W16+X16 -> 0 | AA16: =Y16+Z16 -> 0
A17: =⑦原価詳細!A15 -> ○○ | B17: =⑦原価詳細!F15/1000000 -> 0 | C17: 目標 | E17: =D17 -> 0 | G17: =E17+F17 -> 0 | I17: =G17+H17 -> 0 | K17: =I17+J17 -> 0 | M17: =K17+L17 -> 0 | O17: =M17+N17 -> 0 | Q17: =O17+P17 -> 0 | S17: =Q17+R17 -> 0 | U17: =S17+T17 -> 0 | W17: =U17+V17 -> 0 | Y17: =W17+X17 -> 0 | AA17: =Y17+Z17 -> 0
B18: =B17-D17-F17-H17-J17-L17-N17-P17-R17-T17-V17-X17-Z17 -> 0 | C18: 実績 | E18: =D18 -> 0 | G18: =E18+F18 -> 0 | I18: =G18+H18 -> 0 | K18: =I18+J18 -> 0 | M18: =K18+L18 -> 0 | O18: =M18+N18 -> 0 | Q18: =O18+P18 -> 0 | S18: =Q18+R18 -> 0 | U18: =S18+T18 -> 0 | W18: =U18+V18 -> 0 | Y18: =W18+X18 -> 0 | AA18: =Y18+Z18 -> 0
A19: =⑦原価詳細!A16 -> 〇〇 | B19: =⑦原価詳細!F16/1000000 -> 0 | C19: 目標 | E19: =D19 -> 0 | G19: =E19+F19 -> 0 | I19: =G19+H19 -> 0 | K19: =I19+J19 -> 0 | M19: =K19+L19 -> 0 | O19: =M19+N19 -> 0 | Q19: =O19+P19 -> 0 | S19: =Q19+R19 -> 0 | U19: =S19+T19 -> 0 | W19: =U19+V19 -> 0 | Y19: =W19+X19 -> 0 | AA19: =Y19+Z19 -> 0
B20: =B19-D19-F19-H19-J19-L19-N19-P19-R19-T19-V19-X19-Z19 -> 0 | C20: 実績 | E20: =D20 -> 0 | G20: =E20+F20 -> 0 | I20: =G20+H20 -> 0 | K20: =I20+J20 -> 0 | M20: =K20+L20 -> 0 | O20: =M20+N20 -> 0 | Q20: =O20+P20 -> 0 | S20: =Q20+R20 -> 0 | U20: =S20+T20 -> 0 | W20: =U20+V20 -> 0 | Y20: =W20+X20 -> 0 | AA20: =Y20+Z20 -> 0
A21: =⑦原価詳細!A17 -> ○○ | B21: =⑦原価詳細!F17/1000000 -> 0 | C21: 目標 | E21: =D21 -> 0 | G21: =E21+F21 -> 0 | I21: =G21+H21 -> 0 | K21: =I21+J21 -> 0 | M21: =K21+L21 -> 0 | O21: =M21+N21 -> 0 | Q21: =O21+P21 -> 0 | S21: =Q21+R21 -> 0 | U21: =S21+T21 -> 0 | W21: =U21+V21 -> 0 | Y21: =W21+X21 -> 0 | AA21: =Y21+Z21 -> 0
B22: =B21-D21-F21-H21-J21-L21-N21-P21-R21-T21-V21-X21-Z21 -> 0 | C22: 実績 | E22: =D22 -> 0 | G22: =E22+F22 -> 0 | I22: =G22+H22 -> 0 | K22: =I22+J22 -> 0 | M22: =K22+L22 -> 0 | O22: =M22+N22 -> 0 | Q22: =O22+P22 -> 0 | S22: =Q22+R22 -> 0 | U22: =S22+T22 -> 0 | W22: =U22+V22 -> 0 | Y22: =W22+X22 -> 0 | AA22: =Y22+Z22 -> 0
A23: =⑦原価詳細!A18 -> ○○ | B23: =⑦原価詳細!F18/1000000 -> 0 | C23: 目標 | E23: =D23 -> 0 | G23: =E23+F23 -> 0 | I23: =G23+H23 -> 0 | K23: =I23+J23 -> 0 | M23: =K23+L23 -> 0 | O23: =M23+N23 -> 0 | Q23: =O23+P23 -> 0 | S23: =Q23+R23 -> 0 | U23: =S23+T23 -> 0 | W23: =U23+V23 -> 0 | Y23: =W23+X23 -> 0 | AA23: =Y23+Z23 -> 0
B24: =B23-D23-F23-H23-J23-L23-N23-P23-R23-T23-V23-X23-Z23 -> 0 | C24: 実績 | E24: =D24 -> 0 | G24: =E24+F24 -> 0 | I24: =G24+H24 -> 0 | K24: =I24+J24 -> 0 | M24: =K24+L24 -> 0 | O24: =M24+N24 -> 0 | Q24: =O24+P24 -> 0 | S24: =Q24+R24 -> 0 | U24: =S24+T24 -> 0 | W24: =U24+V24 -> 0 | Y24: =W24+X24 -> 0 | AA24: =Y24+Z24 -> 0
A25: =⑦原価詳細!A19 -> ○○ | B25: =⑦原価詳細!F19/1000000 -> 0 | C25: 目標 | E25: =D25 -> 0 | G25: =E25+F25 -> 0 | I25: =G25+H25 -> 0 | K25: =I25+J25 -> 0 | M25: =K25+L25 -> 0 | O25: =M25+N25 -> 0 | Q25: =O25+P25 -> 0 | S25: =Q25+R25 -> 0 | U25: =S25+T25 -> 0 | W25: =U25+V25 -> 0 | Y25: =W25+X25 -> 0 | AA25: =Y25+Z25 -> 0
B26: =B25-D25-F25-H25-J25-L25-N25-P25-R25-T25-V25-X25-Z25 -> 0 | C26: 実績 | E26: =D26 -> 0 | G26: =E26+F26 -> 0 | I26: =G26+H26 -> 0 | K26: =I26+J26 -> 0 | M26: =K26+L26 -> 0 | O26: =M26+N26 -> 0 | Q26: =O26+P26 -> 0 | S26: =Q26+R26 -> 0 | U26: =S26+T26 -> 0 | W26: =U26+V26 -> 0 | Y26: =W26+X26 -> 0 | AA26: =Y26+Z26 -> 0
A27: =⑦原価詳細!A20 -> ○○ | B27: =⑦原価詳細!F20/1000000 -> 0 | C27: 目標 | E27: =D27 -> 0 | G27: =E27+F27 -> 0 | I27: =G27+H27 -> 0 | K27: =I27+J27 -> 0 | M27: =K27+L27 -> 0 | O27: =M27+N27 -> 0 | Q27: =O27+P27 -> 0 | S27: =Q27+R27 -> 0 | U27: =S27+T27 -> 0 | W27: =U27+V27 -> 0 | Y27: =W27+X27 -> 0 | AA27: =Y27+Z27 -> 0
B28: =B27-D27-F27-H27-J27-L27-N27-P27-R27-T27-V27-X27-Z27 -> 0 | C28: 実績 | E28: =D28 -> 0 | G28: =E28+F28 -> 0 | I28: =G28+H28 -> 0 | K28: =I28+J28 -> 0 | M28: =K28+L28 -> 0 | O28: =M28+N28 -> 0 | Q28: =O28+P28 -> 0 | S28: =Q28+R28 -> 0 | U28: =S28+T28 -> 0 | W28: =U28+V28 -> 0 | Y28: =W28+X28 -> 0 | AA28: =Y28+Z28 -> 0
A29: =⑦原価詳細!A21 -> ○○ | B29: =⑦原価詳細!F21/1000000 -> 0 | C29: 目標 | E29: =D29 -> 0 | G29: =E29+F29 -> 0 | I29: =G29+H29 -> 0 | K29: =I29+J29 -> 0 | M29: =K29+L29 -> 0 | O29: =M29+N29 -> 0 | Q29: =O29+P29 -> 0 | S29: =Q29+R29 -> 0 | U29: =S29+T29 -> 0 | W29: =U29+V29 -> 0 | Y29: =W29+X29 -> 0 | AA29: =Y29+Z29 -> 0
B30: =B29-D29-F29-H29-J29-L29-N29-P29-R29-T29-V29-X29-Z29 -> 0 | C30: 実績 | E30: =D30 -> 0 | G30: =E30+F30 -> 0 | I30: =G30+H30 -> 0 | K30: =I30+J30 -> 0 | M30: =K30+L30 -> 0 | O30: =M30+N30 -> 0 | Q30: =O30+P30 -> 0 | S30: =Q30+R30 -> 0 | U30: =S30+T30 -> 0 | W30: =U30+V30 -> 0 | Y30: =W30+X30 -> 0 | AA30: =Y30+Z30 -> 0
A31: =⑦原価詳細!A22 -> ○○ | B31: =⑦原価詳細!F22/1000000 -> 0 | C31: 目標 | E31: =D31 -> 0 | G31: =E31+F31 -> 0 | I31: =G31+H31 -> 0 | K31: =I31+J31 -> 0 | M31: =K31+L31 -> 0 | O31: =M31+N31 -> 0 | Q31: =O31+P31 -> 0 | S31: =Q31+R31 -> 0 | U31: =S31+T31 -> 0 | W31: =U31+V31 -> 0 | Y31: =W31+X31 -> 0 | AA31: =Y31+Z31 -> 0
B32: =B31-D31-F31-H31-J31-L31-N31-P31-R31-T31-V31-X31-Z31 -> 0 | C32: 実績 | E32: =D32 -> 0 | G32: =E32+F32 -> 0 | I32: =G32+H32 -> 0 | K32: =I32+J32 -> 0 | M32: =K32+L32 -> 0 | O32: =M32+N32 -> 0 | Q32: =O32+P32 -> 0 | S32: =Q32+R32 -> 0 | U32: =S32+T32 -> 0 | W32: =U32+V32 -> 0 | Y32: =W32+X32 -> 0 | AA32: =Y32+Z32 -> 0
A33: =⑦原価詳細!A23 -> ○○ | B33: =⑦原価詳細!F23/1000000 -> 0 | C33: 目標 | E33: =D33 -> 0 | G33: =E33+F33 -> 0 | I33: =G33+H33 -> 0 | K33: =I33+J33 -> 0 | M33: =K33+L33 -> 0 | O33: =M33+N33 -> 0 | Q33: =O33+P33 -> 0 | S33: =Q33+R33 -> 0 | U33: =S33+T33 -> 0 | W33: =U33+V33 -> 0 | Y33: =W33+X33 -> 0 | AA33: =Y33+Z33 -> 0
B34: =B33-D33-F33-H33-J33-L33-N33-P33-R33-T33-V33-X33-Z33 -> 0 | C34: 実績 | E34: =D34 -> 0 | G34: =E34+F34 -> 0 | I34: =G34+H34 -> 0 | K34: =I34+J34 -> 0 | M34: =K34+L34 -> 0 | O34: =M34+N34 -> 0 | Q34: =O34+P34 -> 0 | S34: =Q34+R34 -> 0 | U34: =S34+T34 -> 0 | W34: =U34+V34 -> 0 | Y34: =W34+X34 -> 0 | AA34: =Y34+Z34 -> 0
A35: =⑦原価詳細!A24 -> ○○ | B35: =⑦原価詳細!F24/1000000 -> 0 | C35: 目標 | E35: =D35 -> 0 | G35: =E35+F35 -> 0 | I35: =G35+H35 -> 0 | K35: =I35+J35 -> 0 | M35: =K35+L35 -> 0 | O35: =M35+N35 -> 0 | Q35: =O35+P35 -> 0 | S35: =Q35+R35 -> 0 | U35: =S35+T35 -> 0 | W35: =U35+V35 -> 0 | Y35: =W35+X35 -> 0 | AA35: =Y35+Z35 -> 0
B36: =B35-D35-F35-H35-J35-L35-N35-P35-R35-T35-V35-X35-Z35 -> 0 | C36: 実績 | E36: =D36 -> 0 | G36: =E36+F36 -> 0 | I36: =G36+H36 -> 0 | K36: =I36+J36 -> 0 | M36: =K36+L36 -> 0 | O36: =M36+N36 -> 0 | Q36: =O36+P36 -> 0 | S36: =Q36+R36 -> 0 | U36: =S36+T36 -> 0 | W36: =U36+V36 -> 0 | Y36: =W36+X36 -> 0 | AA36: =Y36+Z36 -> 0
A37: =⑦原価詳細!A25 -> ○○ | B37: =⑦原価詳細!F25/1000000 -> 0 | C37: 目標 | E37: =D37 -> 0 | G37: =E37+F37 -> 0 | I37: =G37+H37 -> 0 | K37: =I37+J37 -> 0 | M37: =K37+L37 -> 0 | O37: =M37+N37 -> 0 | Q37: =O37+P37 -> 0 | S37: =Q37+R37 -> 0 | U37: =S37+T37 -> 0 | W37: =U37+V37 -> 0 | Y37: =W37+X37 -> 0 | AA37: =Y37+Z37 -> 0
B38: =B37-D37-F37-H37-J37-L37-N37-P37-R37-T37-V37-X37-Z37 -> 0 | C38: 実績 | E38: =D38 -> 0 | G38: =E38+F38 -> 0 | I38: =G38+H38 -> 0 | K38: =I38+J38 -> 0 | M38: =K38+L38 -> 0 | O38: =M38+N38 -> 0 | Q38: =O38+P38 -> 0 | S38: =Q38+R38 -> 0 | U38: =S38+T38 -> 0 | W38: =U38+V38 -> 0 | Y38: =W38+X38 -> 0 | AA38: =Y38+Z38 -> 0
A39: =⑦原価詳細!A26 -> ○○ | B39: =⑦原価詳細!F26/1000000 -> 0 | C39: 目標 | E39: =D39 -> 0 | G39: =E39+F39 -> 0 | I39: =G39+H39 -> 0 | K39: =I39+J39 -> 0 | M39: =K39+L39 -> 0 | O39: =M39+N39 -> 0 | Q39: =O39+P39 -> 0 | S39: =Q39+R39 -> 0 | U39: =S39+T39 -> 0 | W39: =U39+V39 -> 0 | Y39: =W39+X39 -> 0 | AA39: =Y39+Z39 -> 0
B40: =B39-D39-F39-H39-J39-L39-N39-P39-R39-T39-V39-X39-Z39 -> 0 | C40: 実績 | E40: =D40 -> 0 | G40: =E40+F40 -> 0 | I40: =G40+H40 -> 0 | K40: =I40+J40 -> 0 | M40: =K40+L40 -> 0 | O40: =M40+N40 -> 0 | Q40: =O40+P40 -> 0 | S40: =Q40+R40 -> 0 | U40: =S40+T40 -> 0 | W40: =U40+V40 -> 0 | Y40: =W40+X40 -> 0 | AA40: =Y40+Z40 -> 0
...

Sheet 利益計画表
A1: 利益計画表
B2: 現状 | C2: 粗利１％UP | D2: 粗利２％UP | E2: 粗利３％UP | F2: 粗利４％UP | G2: 粗利５％UP | H2: 粗利６％UP | I2: 粗利７％UP | J2: 粗利８％UP | K2: 粗利９％UP | L2: 粗利１０％UP | M2: 製作：結城伸太郎
B3: =B6/B4 -> 0.392 | C3: =B3+0.01 -> 0.402 | D3: =C3+0.01 -> 0.412 | E3: =D3+0.01 -> 0.422 | F3: =E3+0.01 -> 0.432 | G3: =F3+0.01 -> 0.442 | H3: =G3+0.01 -> 0.452 | I3: =H3+0.01 -> 0.462 | J3: =I3+0.01 -> 0.472 | ... L3: =K3+0.01 -> 0.492
A4: 売上 | B4: =⑦原価詳細!F31 -> 450000000 | C4: =$B$4 -> 450000000 | D4: =$B$4 -> 450000000 | E4: =$B$4 -> 450000000 | F4: =$B$4 -> 450000000 | G4: =$B$4 -> 450000000 | H4: =$B$4 -> 450000000 | I4: =$B$4 -> 450000000 | J4: =$B$4 -> 450000000 | ... L4: =$B$4 -> 450000000
A5: 変動費 | B5: ='②⑧MQ（未来）'!F3*1000000 -> 2.736e+08 | C5: =C4-C6 -> 2.691e+08 | D5: =D4-D6 -> 2.646e+08 | E5: =E4-E6 -> 2.601e+08 | F5: =F4-F6 -> 2.556e+08 | G5: =G4-G6 -> 2.511e+08 | H5: =H4-H6 -> 2.466e+08 | I5: =I4-I6 -> 2.421e+08 | J5: =J4-J6 -> 2.376e+08 | ... L5: =L4-L6 -> 2.286e+08
A6: 粗利 | B6: =B4-B5 -> 1.764e+08 | C6: =$B$4*C3 -> 1.809e+08 | D6: =$B$4*D3 -> 1.854e+08 | E6: =$B$4*E3 -> 1.899e+08 | F6: =$B$4*F3 -> 1.944e+08 | G6: =$B$4*G3 -> 1.989e+08 | H6: =$B$4*H3 -> 2.034e+08 | I6: =$B$4*I3 -> 2.079e+08 | J6: =$B$4*J3 -> 2.124e+08 | ... L6: =$B$4*L3 -> 2.214e+08
A7: 固定費 | B7: ='②⑧MQ（未来）'!H13*1000000 -> 130400000 | C7: =B7 -> 130400000 | D7: =C7 -> 130400000 | E7: =D7 -> 130400000 | F7: =E7 -> 130400000 | G7: =F7 -> 130400000 | H7: =G7 -> 130400000 | I7: =H7 -> 130400000 | J7: =I7 -> 130400000 | ... L7: =K7 -> 130400000
A8: 営業利益 | B8: =B4-B5-B7 -> 46000000 | C8: =C4-C5-C7 -> 50500000 | D8: =D4-D5-D7 -> 55000000 | E8: =E4-E5-E7 -> 59500000 | F8: =F4-F5-F7 -> 64000000 | G8: =G4-G5-G7 -> 68500000 | H8: =H4-H5-H7 -> 73000000 | I8: =I4-I5-I7 -> 77500000 | ... L8: =L4-L5-L7 -> 91000000
A9: 益率 | B9: =B8/B4 -> 0.10222222 | C9: =C8/C4 -> 0.11222222 | D9: =D8/D4 -> 0.12222222 | E9: =E8/E4 -> 0.13222222 | F9: =F8/F4 -> 0.14222222 | G9: =G8/G4 -> 0.15222222 | H9: =H8/H4 -> 0.16222222 | I9: =I8/I4 -> 0.17222222 | ... L9: =L8/L4 -> 0.20222222
B10: 現状 | C10: 粗利１％DOWN | D10: 粗利２％DOWN | E10: 粗利３％DOWN | F10: 粗利４％DOWN | G10: 粗利５％DOWN | H10: 粗利６％DOWN | I10: 粗利７％DOWN | J10: 粗利８％DOWN | K10: 粗利９％DOWN | L10: 粗利１０％DOWN
C11: =B3-0.01 -> 0.382 | D11: =C11-0.01 -> 0.372 | E11: =D11-0.01 -> 0.362 | F11: =E11-0.01 -> 0.352 | G11: =F11-0.01 -> 0.342 | H11: =G11-0.01 -> 0.332 | I11: =H11-0.01 -> 0.322 | J11: =I11-0.01 -> 0.312 | K11: =J11-0.01 -> 0.302 | L11: =K11-0.01 -> 0.292
A12: 売上 | B12: =$B$4 -> 450000000 | C12: =$B$4 -> 450000000 | D12: =$B$4 -> 450000000 | E12: =$B$4 -> 450000000 | F12: =$B$4 -> 450000000 | G12: =$B$4 -> 450000000 | H12: =$B$4 -> 450000000 | I12: =$B$4 -> 450000000 | ... L12: =$B$4 -> 450000000
A13: 変動費 | B13: 279200000 | C13: =C12-C14 -> 2.781e+08 | D13: =D12-D14 -> 2.826e+08 | E13: =E12-E14 -> 2.871e+08 | F13: =F12-F14 -> 291600000 | G13: =G12-G14 -> 296100000 | H13: =H12-H14 -> 300600000 | I13: =I12-I14 -> 305100000 | J13: =J12-J14 -> 309600000 | ... L13: =L12-L14 -> 318600000
A14: 粗利 | B14: 170800000 | C14: =$B$4*C11 -> 1.719e+08 | D14: =$B$4*D11 -> 1.674e+08 | E14: =$B$4*E11 -> 1.629e+08 | F14: =$B$4*F11 -> 1.584e+08 | G14: =$B$4*G11 -> 1.539e+08 | H14: =$B$4*H11 -> 1.494e+08 | I14: =$B$4*I11 -> 1.449e+08 | J14: =$B$4*J11 -> 1.404e+08 | ... L14: =$B$4*L11 -> 1.314e+08
A15: 固定費 | B15: ='②⑧MQ（未来）'!H13*1000000 -> 130400000 | C15: =B15 -> 130400000 | D15: =C15 -> 130400000 | E15: =D15 -> 130400000 | F15: =E15 -> 130400000 | G15: =F15 -> 130400000 | H15: =G15 -> 130400000 | I15: =H15 -> 130400000 | J15: =I15 -> 130400000 | ... L15: =K15 -> 130400000
A16: 営業利益 | B16: 45900000 | C16: =C12-C13-C15 -> 41500000 | D16: =D12-D13-D15 -> 37000000 | E16: =E12-E13-E15 -> 32500000 | F16: =F12-F13-F15 -> 28000000 | G16: =G12-G13-G15 -> 23500000 | H16: =H12-H13-H15 -> 19000000 | I16: =I12-I13-I15 -> 14500000 | J16: =J12-J13-J15 -> 10000000 | ... L16: =L12-L13-L15 -> 1000000
A17: 益率 | B17: =B8/B4 -> 0.10222222 | C17: =C16/C12 -> 0.092222222 | D17: =D16/D12 -> 0.082222222 | E17: =E16/E12 -> 0.072222222 | F17: =F16/F12 -> 0.062222222 | G17: =G16/G12 -> 0.052222222 | H17: =H16/H12 -> 0.042222222 | I17: =I16/I12 -> 0.032222222 | J17: =J16/J12 -> 0.022222222 | ... L17: =L16/L12 -> 0.0022222222
A18: 粗利が増えれば純利益が増えます。 | D18: メモ
A19: しかし１０％落とすと・・・？
